<?xml version="1.0" ?>
<!-- =================================================================================== -->
<!-- |    This document was autogenerated by xacro from mirabb.xacro                   | -->
<!-- |    EDITING THIS FILE BY HAND IS NOT RECOMMENDED                                 | -->
<!-- =================================================================================== -->
<robot name="mirabb">
  <material name="silver_default">
    <color rgba="0.700 0.700 0.700 1.000"/>
  </material>
  <material name="opaque636363">
    <color rgba="0.25098039215686274 0.25098039215686274 0.25098039215686274 1.0"/>
  </material>
  <material name="opaque25500_1_1">
    <color rgba="0.14901960784313725 0.9607843137254902 0.49019607843137253 1.0"/>
  </material>
  <material name="opaque25500_1">
    <color rgba="0.14901960784313725 0.3254901960784314 0.9607843137254902 1.0"/>
  </material>
  <material name="opaque25500">
    <color rgba="1.0 0.0 0.0 1.0"/>
  </material>
  <material name="powder_coat_rough_grey">
    <color rgba="0.8235294117647058 0.8941176470588236 0.9333333333333333 1.0"/>
  </material>
  <material name="opaque215215215">
    <color rgba="0.8431372549019608 0.8431372549019608 0.8431372549019608 1.0"/>
  </material>
  <material name="opaque128128128">
    <color rgba="0.5019607843137255 0.5019607843137255 0.5019607843137255 1.0"/>
  </material>
  <material name="paint_metallic_blue">
    <color rgba="0.18823529411764706 0.23137254901960785 0.5882352941176471 1.0"/>
  </material>
  <material name="paint_metallic_silver">
    <color rgba="0.984313725490196 0.9803921568627451 0.9607843137254902 1.0"/>
  </material>
  <material name="paint_metallic_red">
    <color rgba="0.7686274509803922 0.20784313725490197 0.15294117647058825 1.0"/>
  </material>
  <material name="generic">
    <color rgba="0.3137254901960784 0.3137254901960784 0.3137254901960784 1.0"/>
  </material>
  <transmission name="joint_Base_LeftWheel_tran">
    <type>transmission_interface/SimpleTransmission</type>
    <joint name="joint_Base_LeftWheel">
      <hardwareInterface>hardware_interface/EffortJointInterface</hardwareInterface>
    </joint>
    <actuator name="joint_Base_LeftWheel_actr">
      <hardwareInterface>hardware_interface/EffortJointInterface</hardwareInterface>
      <mechanicalReduction>1</mechanicalReduction>
    </actuator>
  </transmission>
  <transmission name="joint_Base_RightWheel_tran">
    <type>transmission_interface/SimpleTransmission</type>
    <joint name="joint_Base_RightWheel">
      <hardwareInterface>hardware_interface/EffortJointInterface</hardwareInterface>
    </joint>
    <actuator name="joint_Base_RightWheel_actr">
      <hardwareInterface>hardware_interface/EffortJointInterface</hardwareInterface>
      <mechanicalReduction>1</mechanicalReduction>
    </actuator>
  </transmission>
  <transmission name="joint_Base_rear_right_caster_tran">
    <type>transmission_interface/SimpleTransmission</type>
    <joint name="joint_Base_rear_right_caster">
      <hardwareInterface>hardware_interface/EffortJointInterface</hardwareInterface>
    </joint>
    <actuator name="joint_Base_rear_right_caster_actr">
      <hardwareInterface>hardware_interface/EffortJointInterface</hardwareInterface>
      <mechanicalReduction>1</mechanicalReduction>
    </actuator>
  </transmission>
  <transmission name="joint_Base_rear_left_caster_tran">
    <type>transmission_interface/SimpleTransmission</type>
    <joint name="joint_Base_rear_left_caster">
      <hardwareInterface>hardware_interface/EffortJointInterface</hardwareInterface>
    </joint>
    <actuator name="joint_Base_rear_left_caster_actr">
      <hardwareInterface>hardware_interface/EffortJointInterface</hardwareInterface>
      <mechanicalReduction>1</mechanicalReduction>
    </actuator>
  </transmission>
  <transmission name="joint_Base_front_right_caster_tran">
    <type>transmission_interface/SimpleTransmission</type>
    <joint name="joint_Base_front_right_caster">
      <hardwareInterface>hardware_interface/EffortJointInterface</hardwareInterface>
    </joint>
    <actuator name="joint_Base_front_right_caster_actr">
      <hardwareInterface>hardware_interface/EffortJointInterface</hardwareInterface>
      <mechanicalReduction>1</mechanicalReduction>
    </actuator>
  </transmission>
  <transmission name="joint_Base_front_left_caster_tran">
    <type>transmission_interface/SimpleTransmission</type>
    <joint name="joint_Base_front_left_caster">
      <hardwareInterface>hardware_interface/EffortJointInterface</hardwareInterface>
    </joint>
    <actuator name="joint_Base_front_left_caster_actr">
      <hardwareInterface>hardware_interface/EffortJointInterface</hardwareInterface>
      <mechanicalReduction>1</mechanicalReduction>
    </actuator>
  </transmission>
  <transmission name="joint1_tran">
    <type>transmission_interface/SimpleTransmission</type>
    <joint name="joint1">
      <!-- <hardwareInterface>hardware_interface/EffortJointInterface</hardwareInterface> -->
      <hardwareInterface>hardware_interface/PositionJointInterface</hardwareInterface>
    </joint>
    <actuator name="joint1_actr">
      <!-- <hardwareInterface>hardware_interface/EffortJointInterface</hardwareInterface> -->
      <hardwareInterface>hardware_interface/PositionJointInterface</hardwareInterface>
      <mechanicalReduction>1</mechanicalReduction>
    </actuator>
  </transmission>
  <transmission name="joint2_tran">
    <type>transmission_interface/SimpleTransmission</type>
    <joint name="joint2">
      <!-- <hardwareInterface>hardware_interface/EffortJointInterface</hardwareInterface> -->
      <hardwareInterface>hardware_interface/PositionJointInterface</hardwareInterface>
    </joint>
    <actuator name="joint2_actr">
      <!-- <hardwareInterface>hardware_interface/EffortJointInterface</hardwareInterface> -->
      <hardwareInterface>hardware_interface/PositionJointInterface</hardwareInterface>
      <mechanicalReduction>1</mechanicalReduction>
    </actuator>
  </transmission>
  <transmission name="joint3_tran">
    <type>transmission_interface/SimpleTransmission</type>
    <joint name="joint3">
      <!-- <hardwareInterface>hardware_interface/EffortJointInterface</hardwareInterface> -->
      <hardwareInterface>hardware_interface/PositionJointInterface</hardwareInterface>
    </joint>
    <actuator name="joint3_actr">
      <!-- <hardwareInterface>hardware_interface/EffortJointInterface</hardwareInterface> -->
      <hardwareInterface>hardware_interface/PositionJointInterface</hardwareInterface>
      <mechanicalReduction>1</mechanicalReduction>
    </actuator>
  </transmission>
  <transmission name="joint4_tran">
    <type>transmission_interface/SimpleTransmission</type>
    <joint name="joint4">
      <!-- <hardwareInterface>hardware_interface/EffortJointInterface</hardwareInterface> -->
      <hardwareInterface>hardware_interface/PositionJointInterface</hardwareInterface>
    </joint>
    <actuator name="joint4_actr">
      <!-- <hardwareInterface>hardware_interface/EffortJointInterface</hardwareInterface> -->
      <hardwareInterface>hardware_interface/PositionJointInterface</hardwareInterface>
      <mechanicalReduction>1</mechanicalReduction>
    </actuator>
  </transmission>
  <transmission name="joint5_tran">
    <type>transmission_interface/SimpleTransmission</type>
    <joint name="joint5">
      <!-- <hardwareInterface>hardware_interface/EffortJointInterface</hardwareInterface> -->
      <hardwareInterface>hardware_interface/PositionJointInterface</hardwareInterface>
    </joint>
    <actuator name="joint5_actr">
      <!-- <hardwareInterface>hardware_interface/EffortJointInterface</hardwareInterface> -->
      <hardwareInterface>hardware_interface/PositionJointInterface</hardwareInterface>
      <mechanicalReduction>1</mechanicalReduction>
    </actuator>
  </transmission>
  <transmission name="joint6_tran">
    <type>transmission_interface/SimpleTransmission</type>
    <joint name="joint6">
      <!-- <hardwareInterface>hardware_interface/EffortJointInterface</hardwareInterface> -->
      <hardwareInterface>hardware_interface/PositionJointInterface</hardwareInterface>
    </joint>
    <actuator name="joint6_actr">
      <!-- <hardwareInterface>hardware_interface/EffortJointInterface</hardwareInterface> -->
      <hardwareInterface>hardware_interface/PositionJointInterface</hardwareInterface>
      <mechanicalReduction>1</mechanicalReduction>
    </actuator>
  </transmission>
  <transmission name="joint8_tran">
    <type>transmission_interface/SimpleTransmission</type>
    <joint name="joint8">
      <!-- <hardwareInterface>hardware_interface/EffortJointInterface</hardwareInterface> -->
      <hardwareInterface>hardware_interface/PositionJointInterface</hardwareInterface>
    </joint>
    <actuator name="joint8_actr">
      <!-- <hardwareInterface>hardware_interface/EffortJointInterface</hardwareInterface> -->
      <hardwareInterface>hardware_interface/PositionJointInterface</hardwareInterface>
      <mechanicalReduction>1</mechanicalReduction>
    </actuator>
  </transmission>
  <transmission name="joint9_tran">
    <type>transmission_interface/SimpleTransmission</type>
    <joint name="joint9">
      <!-- <hardwareInterface>hardware_interface/EffortJointInterface</hardwareInterface> -->
      <hardwareInterface>hardware_interface/PositionJointInterface</hardwareInterface>
    </joint>
    <actuator name="joint9_actr">
      <!-- <hardwareInterface>hardware_interface/EffortJointInterface</hardwareInterface> -->
      <hardwareInterface>hardware_interface/PositionJointInterface</hardwareInterface>
      <mechanicalReduction>1</mechanicalReduction>
    </actuator>
  </transmission>
  <transmission name="joint10_tran">
    <type>transmission_interface/SimpleTransmission</type>
    <joint name="joint10">
      <!-- <hardwareInterface>hardware_interface/EffortJointInterface</hardwareInterface> -->
      <hardwareInterface>hardware_interface/PositionJointInterface</hardwareInterface>
    </joint>
    <actuator name="joint10_actr">
      <!-- <hardwareInterface>hardware_interface/EffortJointInterface</hardwareInterface> -->
      <hardwareInterface>hardware_interface/PositionJointInterface</hardwareInterface>
      <mechanicalReduction>1</mechanicalReduction>
    </actuator>
  </transmission>
  <transmission name="joint11_tran">
    <type>transmission_interface/SimpleTransmission</type>
    <joint name="joint11">
      <!-- <hardwareInterface>hardware_interface/EffortJointInterface</hardwareInterface> -->
      <hardwareInterface>hardware_interface/PositionJointInterface</hardwareInterface>
    </joint>
    <actuator name="joint11_actr">
      <!-- <hardwareInterface>hardware_interface/EffortJointInterface</hardwareInterface> -->
      <hardwareInterface>hardware_interface/PositionJointInterface</hardwareInterface>
      <mechanicalReduction>1</mechanicalReduction>
    </actuator>
  </transmission>
  <!-- <gazebo>
  <plugin name="control" filename="libgazebo_ros_control.so"/>
</gazebo> -->
  <gazebo>
    <plugin filename="libgazebo_ros_control.so" name="gazebo_ros_control">
      <robotNamespace>/mirabb</robotNamespace>
      <robotSimType>gazebo_ros_control/DefaultRobotHWSim</robotSimType>
    </plugin>
  </gazebo>
  <gazebo reference="base_link">
    <material>Gazebo/Silver</material>
    <mu1>0.2</mu1>
    <mu2>0.2</mu2>
    <selfCollide>true</selfCollide>
    <gravity>true</gravity>
  </gazebo>
  <gazebo reference="mir_left_drive_wheel_1">
    <material>Gazebo/Silver</material>
    <mu1>0.2</mu1>
    <mu2>0.2</mu2>
    <selfCollide>true</selfCollide>
  </gazebo>
  <gazebo reference="mir_right_drive_wheel_1">
    <material>Gazebo/Silver</material>
    <mu1>0.2</mu1>
    <mu2>0.2</mu2>
    <selfCollide>true</selfCollide>
  </gazebo>
  <gazebo reference="mir_rear_right_caster_1">
    <material>Gazebo/Silver</material>
    <mu1>0.2</mu1>
    <mu2>0.2</mu2>
    <selfCollide>true</selfCollide>
  </gazebo>
  <gazebo reference="mir_rear_left_caster_1">
    <material>Gazebo/Silver</material>
    <mu1>0.2</mu1>
    <mu2>0.2</mu2>
    <selfCollide>true</selfCollide>
  </gazebo>
  <gazebo reference="mir_front_right_caster_1">
    <material>Gazebo/Silver</material>
    <mu1>0.2</mu1>
    <mu2>0.2</mu2>
    <selfCollide>true</selfCollide>
  </gazebo>
  <gazebo reference="mir_front_left_caster_1">
    <material>Gazebo/Silver</material>
    <mu1>0.2</mu1>
    <mu2>0.2</mu2>
    <selfCollide>true</selfCollide>
  </gazebo>
  <gazebo reference="link0_1">
    <material>Gazebo/Silver</material>
    <mu1>0.2</mu1>
    <mu2>0.2</mu2>
    <selfCollide>true</selfCollide>
  </gazebo>
  <gazebo reference="link1_1">
    <material>Gazebo/Silver</material>
    <mu1>0.2</mu1>
    <mu2>0.2</mu2>
    <selfCollide>true</selfCollide>
  </gazebo>
  <gazebo reference="link2_1">
    <material>Gazebo/Silver</material>
    <mu1>0.2</mu1>
    <mu2>0.2</mu2>
    <selfCollide>true</selfCollide>
  </gazebo>
  <gazebo reference="link3_1">
    <material>Gazebo/Silver</material>
    <mu1>0.2</mu1>
    <mu2>0.2</mu2>
    <selfCollide>true</selfCollide>
  </gazebo>
  <gazebo reference="link4_1">
    <material>Gazebo/Silver</material>
    <mu1>0.2</mu1>
    <mu2>0.2</mu2>
    <selfCollide>true</selfCollide>
  </gazebo>
  <gazebo reference="link5_1">
    <material>Gazebo/Silver</material>
    <mu1>0.2</mu1>
    <mu2>0.2</mu2>
    <selfCollide>true</selfCollide>
  </gazebo>
  <gazebo reference="link6_1">
    <material>Gazebo/Silver</material>
    <mu1>0.2</mu1>
    <mu2>0.2</mu2>
    <selfCollide>true</selfCollide>
  </gazebo>
  <gazebo reference="link7_1">
    <material>Gazebo/Silver</material>
    <mu1>0.2</mu1>
    <mu2>0.2</mu2>
    <selfCollide>true</selfCollide>
  </gazebo>
  <gazebo reference="link11_1">
    <material>Gazebo/Silver</material>
    <mu1>0.2</mu1>
    <mu2>0.2</mu2>
    <selfCollide>true</selfCollide>
  </gazebo>
  <gazebo reference="link10_1">
    <material>Gazebo/Silver</material>
    <mu1>0.2</mu1>
    <mu2>0.2</mu2>
    <selfCollide>true</selfCollide>
  </gazebo>
  <gazebo reference="link9_1">
    <material>Gazebo/Silver</material>
    <mu1>0.2</mu1>
    <mu2>0.2</mu2>
    <selfCollide>true</selfCollide>
  </gazebo>
  <gazebo reference="link8_1">
    <material>Gazebo/Silver</material>
    <mu1>0.2</mu1>
    <mu2>0.2</mu2>
    <selfCollide>true</selfCollide>
  </gazebo>
  <link name="base_link">
    <inertial>
      <origin rpy="0 0 0" xyz="-0.14772812309663302 -0.023206697854912604 0.4203334227386186"/>
      <mass value="1000"/>
      <inertia ixx="199.757361" ixy="11.317127" ixz="56.773936" iyy="263.585665" iyz="-1.492251" izz="251.283031"/>
    </inertial>
    <visual>
      <origin rpy="0 0 0" xyz="0 0 0"/>
      <geometry>
        <mesh filename="package://mirabb_description/meshes/base_link.stl" scale="0.001 0.001 0.001"/>
      </geometry>
      <material name="opaque636363"/>
    </visual>
    <collision>
      <origin rpy="0 0 0" xyz="0 0 0"/>
      <geometry>
        <mesh filename="package://mirabb_description/meshes/base_link.stl" scale="0.001 0.001 0.001"/>
      </geometry>
    </collision>
  </link>
  <link name="world"/>
  <joint name="fixed" type="fixed">
    <parent link="world"/>
    <child link="base_link"/>
  </joint>
  <link name="mir_left_drive_wheel_1">
    <inertial>
      <origin rpy="0 0 0" xyz="2.1315413548247345e-07 1.7219884374530814e-06 -6.709368598589727e-06"/>
      <mass value="5.294052840904085"/>
      <inertia ixx="0.021658" ixy="0.0" ixz="-0.0" iyy="0.041149" iyz="1e-06" izz="0.021656"/>
    </inertial>
    <visual>
      <origin rpy="0 0 0" xyz="0.000842 0.331703 -0.102346"/>
      <geometry>
        <mesh filename="package://mirabb_description/meshes/mir_left_drive_wheel_1.stl" scale="0.001 0.001 0.001"/>
      </geometry>
      <material name="opaque25500_1_1"/>
    </visual>
    <collision>
      <origin rpy="0 0 0" xyz="0.000842 0.331703 -0.102346"/>
      <geometry>
        <mesh filename="package://mirabb_description/meshes/mir_left_drive_wheel_1.stl" scale="0.001 0.001 0.001"/>
      </geometry>
    </collision>
  </link>
  <link name="mir_right_drive_wheel_1">
    <inertial>
      <origin rpy="0 0 0" xyz="7.484477992811224e-07 -2.2718773015073523e-06 -6.709368683271988e-06"/>
      <mass value="5.294052840904829"/>
      <inertia ixx="0.021658" ixy="0.0" ixz="0.0" iyy="0.041149" iyz="-1e-06" izz="0.021656"/>
    </inertial>
    <visual>
      <origin rpy="0 0 0" xyz="0.000842 -0.330477 -0.102346"/>
      <geometry>
        <mesh filename="package://mirabb_description/meshes/mir_right_drive_wheel_1.stl" scale="0.001 0.001 0.001"/>
      </geometry>
      <material name="opaque25500_1_1"/>
    </visual>
    <collision>
      <origin rpy="0 0 0" xyz="0.000842 -0.330477 -0.102346"/>
      <geometry>
        <mesh filename="package://mirabb_description/meshes/mir_right_drive_wheel_1.stl" scale="0.001 0.001 0.001"/>
      </geometry>
    </collision>
  </link>
  <link name="mir_rear_right_caster_1">
    <inertial>
      <origin rpy="0 0 0" xyz="4.808006703882484e-07 -2.749445809913098e-07 -2.1737521140735572e-07"/>
      <mass value="2.8340302939762845"/>
      <inertia ixx="0.00334" ixy="-0.0" ixz="-0.0" iyy="0.003822" iyz="-0.0" izz="0.00334"/>
    </inertial>
    <visual>
      <origin rpy="0 0 0" xyz="0.587342 -0.324887 -0.052346"/>
      <geometry>
        <mesh filename="package://mirabb_description/meshes/mir_rear_right_caster_1.stl" scale="0.001 0.001 0.001"/>
      </geometry>
      <material name="opaque25500_1"/>
    </visual>
    <collision>
      <origin rpy="0 0 0" xyz="0.587342 -0.324887 -0.052346"/>
      <geometry>
        <mesh filename="package://mirabb_description/meshes/mir_rear_right_caster_1.stl" scale="0.001 0.001 0.001"/>
      </geometry>
    </collision>
  </link>
  <link name="mir_rear_left_caster_1">
    <inertial>
      <origin rpy="0 0 0" xyz="4.808008184919998e-07 -2.749445659477878e-07 -2.1737514686176462e-07"/>
      <mass value="3.2863508269475776"/>
      <inertia ixx="0.00407" ixy="-0.0" ixz="0.0" iyy="0.004808" iyz="-0.0" izz="0.00407"/>
    </inertial>
    <visual>
      <origin rpy="0 0 0" xyz="0.587342 0.324113 -0.052346"/>
      <geometry>
        <mesh filename="package://mirabb_description/meshes/mir_rear_left_caster_1.stl" scale="0.001 0.001 0.001"/>
      </geometry>
      <material name="opaque25500_1"/>
    </visual>
    <collision>
      <origin rpy="0 0 0" xyz="0.587342 0.324113 -0.052346"/>
      <geometry>
        <mesh filename="package://mirabb_description/meshes/mir_rear_left_caster_1.stl" scale="0.001 0.001 0.001"/>
      </geometry>
    </collision>
  </link>
  <link name="mir_front_right_caster_1">
    <inertial>
      <origin rpy="0 0 0" xyz="-4.941080842812973e-07 -2.749443341332203e-07 -4.5438580856260735e-07"/>
      <mass value="3.286350826947556"/>
      <inertia ixx="0.00407" ixy="-0.0" ixz="-0.0" iyy="0.004808" iyz="-0.0" izz="0.00407"/>
    </inertial>
    <visual>
      <origin rpy="0 0 0" xyz="-0.492668 -0.324887 -0.052365"/>
      <geometry>
        <mesh filename="package://mirabb_description/meshes/mir_front_right_caster_1.stl" scale="0.001 0.001 0.001"/>
      </geometry>
      <material name="opaque25500_1"/>
    </visual>
    <collision>
      <origin rpy="0 0 0" xyz="-0.492668 -0.324887 -0.052365"/>
      <geometry>
        <mesh filename="package://mirabb_description/meshes/mir_front_right_caster_1.stl" scale="0.001 0.001 0.001"/>
      </geometry>
    </collision>
  </link>
  <link name="mir_front_left_caster_1">
    <inertial>
      <origin rpy="0 0 0" xyz="-4.941078886600003e-07 -2.7494431548147347e-07 -4.543858788466637e-07"/>
      <mass value="3.2863508269475816"/>
      <inertia ixx="0.00407" ixy="0.0" ixz="-0.0" iyy="0.004808" iyz="-0.0" izz="0.00407"/>
    </inertial>
    <visual>
      <origin rpy="0 0 0" xyz="-0.492668 0.324113 -0.052365"/>
      <geometry>
        <mesh filename="package://mirabb_description/meshes/mir_front_left_caster_1.stl" scale="0.001 0.001 0.001"/>
      </geometry>
      <material name="opaque25500_1"/>
    </visual>
    <collision>
      <origin rpy="0 0 0" xyz="-0.492668 0.324113 -0.052365"/>
      <geometry>
        <mesh filename="package://mirabb_description/meshes/mir_front_left_caster_1.stl" scale="0.001 0.001 0.001"/>
      </geometry>
    </collision>
  </link>
  <link name="link0_1">
    <inertial>
      <origin rpy="0 0 0" xyz="-0.09119346561175606 0.0003630237210969841 0.07246431742776649"/>
      <mass value="2.37"/>
      <inertia ixx="3.322456" ixy="0.030784" ixz="0.455197" iyy="6.746895" iyz="0.001141" izz="9.112071"/>
    </inertial>
    <visual>
      <origin rpy="0 0 0" xyz="-0.357783 0.000662 -0.322346"/>
      <geometry>
        <mesh filename="package://mirabb_description/meshes/link0_1.stl" scale="0.001 0.001 0.001"/>
      </geometry>
      <material name="powder_coat_rough_grey"/>
    </visual>
    <collision>
      <origin rpy="0 0 0" xyz="-0.357783 0.000662 -0.322346"/>
      <geometry>
        <mesh filename="package://mirabb_description/meshes/link0_1.stl" scale="0.001 0.001 0.001"/>
      </geometry>
    </collision>
  </link>
  <link name="link1_1">
    <inertial>
      <origin rpy="0 0 0" xyz="0.0770381921903589 0.02468988684405638 0.24069822644139682"/>
      <mass value="3.32"/>
      <inertia ixx="8.732818" ixy="-0.760548" ixz="-2.349544" iyy="11.378244" iyz="-0.812185" izz="9.105966"/>
    </inertial>
    <visual>
      <origin rpy="0 0 0" xyz="-0.357783 0.000662 -0.475846"/>
      <geometry>
        <mesh filename="package://mirabb_description/meshes/link1_1.stl" scale="0.001 0.001 0.001"/>
      </geometry>
      <material name="powder_coat_rough_grey"/>
    </visual>
    <collision>
      <origin rpy="0 0 0" xyz="-0.357783 0.000662 -0.475846"/>
      <geometry>
        <mesh filename="package://mirabb_description/meshes/link1_1.stl" scale="0.001 0.001 0.001"/>
      </geometry>
    </collision>
  </link>
  <link name="link2_1">
    <inertial>
      <origin rpy="0 0 0" xyz="8.115108053485809e-05 -0.04807066318993641 0.39677546222613913"/>
      <mass value="2.20"/>
      <inertia ixx="17.032393" ixy="-0.000226" ixz="0.002216" iyy="17.64881" iyz="0.57807" izz="1.263078"/>
    </inertial>
    <visual>
      <origin rpy="0 0 0" xyz="-0.532783 0.123162 -0.811346"/>
      <geometry>
        <mesh filename="package://mirabb_description/meshes/link2_1.stl" scale="0.001 0.001 0.001"/>
      </geometry>
      <material name="powder_coat_rough_grey"/>
    </visual>
    <collision>
      <origin rpy="0 0 0" xyz="-0.532783 0.123162 -0.811346"/>
      <geometry>
        <mesh filename="package://mirabb_description/meshes/link2_1.stl" scale="0.001 0.001 0.001"/>
      </geometry>
    </collision>
  </link>
  <link name="link3_1">
    <inertial>
      <origin rpy="0 0 0" xyz="0.04071241501864575 0.19846588331938803 0.11876174508797432"/>
      <mass value="4.00"/>
      <inertia ixx="8.893944" ixy="0.577245" ixz="-0.921475" iyy="10.887964" iyz="-0.110791" izz="8.946809"/>
    </inertial>
    <visual>
      <origin rpy="0 0 0" xyz="-0.532783 0.149862 -1.711346"/>
      <geometry>
        <mesh filename="package://mirabb_description/meshes/link3_1.stl" scale="0.001 0.001 0.001"/>
      </geometry>
      <material name="powder_coat_rough_grey"/>
    </visual>
    <collision>
      <origin rpy="0 0 0" xyz="-0.532783 0.149862 -1.711346"/>
      <geometry>
        <mesh filename="package://mirabb_description/meshes/link3_1.stl" scale="0.001 0.001 0.001"/>
      </geometry>
    </collision>
  </link>
  <link name="link4_1">
    <inertial>
      <origin rpy="0 0 0" xyz="0.3931328503470747 -0.001975761568746799 -0.002846156235639885"/>
      <mass value="0.87"/>
      <inertia ixx="0.41803" ixy="0.044332" ixz="0.018011" iyy="3.624483" iyz="0.000227" izz="3.763004"/>
    </inertial>
    <visual>
      <origin rpy="0 0 0" xyz="-0.872883 0.000662 -1.886346"/>
      <geometry>
        <mesh filename="package://mirabb_description/meshes/link4_1.stl" scale="0.001 0.001 0.001"/>
      </geometry>
      <material name="powder_coat_rough_grey"/>
    </visual>
    <collision>
      <origin rpy="0 0 0" xyz="-0.872883 0.000662 -1.886346"/>
      <geometry>
        <mesh filename="package://mirabb_description/meshes/link4_1.stl" scale="0.001 0.001 0.001"/>
      </geometry>
    </collision>
  </link>
  <link name="link5_1">
    <inertial>
      <origin rpy="0 0 0" xyz="-0.001050837673909566 -0.06745178444475677 0.000400066383309694"/>
      <mass value="0.11"/>
      <inertia ixx="0.023766" ixy="-6e-06" ixz="-0.000134" iyy="0.024654" iyz="-4e-05" izz="0.026173"/>
    </inertial>
    <visual>
      <origin rpy="0 0 0" xyz="-1.492783 -0.063338 -1.886346"/>
      <geometry>
        <mesh filename="package://mirabb_description/meshes/link5_1.stl" scale="0.001 0.001 0.001"/>
      </geometry>
      <material name="opaque215215215"/>
    </visual>
    <collision>
      <origin rpy="0 0 0" xyz="-1.492783 -0.063338 -1.886346"/>
      <geometry>
        <mesh filename="package://mirabb_description/meshes/link5_1.stl" scale="0.001 0.001 0.001"/>
      </geometry>
    </collision>
  </link>
  <link name="link6_1">
    <inertial>
      <origin rpy="0 0 0" xyz="0.04834495659572857 -0.0002895257483309458 0.00013833881264391223"/>
      <mass value="0.2088759832475839"/>
      <inertia ixx="0.002956" ixy="6e-06" ixz="-2e-06" iyy="0.002242" iyz="-2.1e-05" izz="0.002257"/>
    </inertial>
    <visual>
      <origin rpy="0 0 0" xyz="-1.557783 0.000662 -1.886346"/>
      <geometry>
        <mesh filename="package://mirabb_description/meshes/link6_1.stl" scale="0.001 0.001 0.001"/>
      </geometry>
      <material name="opaque128128128"/>
    </visual>
    <collision>
      <origin rpy="0 0 0" xyz="-1.557783 0.000662 -1.886346"/>
      <geometry>
        <mesh filename="package://mirabb_description/meshes/link6_1.stl" scale="0.001 0.001 0.001"/>
      </geometry>
    </collision>
  </link>
  <link name="link7_1">
    <inertial>
      <origin rpy="0 0 0" xyz="0.09435402654960545 -0.024443476502948997 -0.1809282457600363"/>
      <mass value="0.18"/>
      <inertia ixx="0.453826" ixy="-0.000281" ixz="0.036009" iyy="0.490217" iyz="0.009786" izz="0.136509"/>
    </inertial>
    <visual>
      <origin rpy="0 0 0" xyz="-1.627783 -0.024338 -1.929647"/>
      <geometry>
        <mesh filename="package://mirabb_description/meshes/link7_1.stl" scale="0.001 0.001 0.001"/>
      </geometry>
      <material name="paint_metallic_blue"/>
    </visual>
    <collision>
      <origin rpy="0 0 0" xyz="-1.627783 -0.024338 -1.929647"/>
      <geometry>
        <mesh filename="package://mirabb_description/meshes/link7_1.stl" scale="0.001 0.001 0.001"/>
      </geometry>
    </collision>
  </link>
  <link name="link11_1">
    <inertial>
      <origin rpy="0 0 0" xyz="0.004010304521571584 0.07995109560914467 -0.13300869834630413"/>
      <mass value="0.11"/>
      <inertia ixx="0.089057" ixy="-2.8e-05" ixz="0.002048" iyy="0.072156" iyz="0.0" izz="0.030313"/>
    </inertial>
    <visual>
      <origin rpy="0 0 0" xyz="-1.847783 0.080662 -1.750846"/>
      <geometry>
        <mesh filename="package://mirabb_description/meshes/link11_1.stl" scale="0.001 0.001 0.001"/>
      </geometry>
      <material name="paint_metallic_silver"/>
    </visual>
    <collision>
      <origin rpy="0 0 0" xyz="-1.847783 0.080662 -1.750846"/>
      <geometry>
        <mesh filename="package://mirabb_description/meshes/link11_1.stl" scale="0.001 0.001 0.001"/>
      </geometry>
    </collision>
  </link>
  <link name="link10_1">
    <inertial>
      <origin rpy="0 0 0" xyz="0.06094357946520934 3.5250784968430225e-08 -0.022431829490297206"/>
      <mass value="0.27783433343628725"/>
      <inertia ixx="0.022484" ixy="0.0" ixz="0.004273" iyy="0.019086" iyz="-0.0" izz="0.023473"/>
    </inertial>
    <visual>
      <origin rpy="0 0 0" xyz="-1.770283 0.000662 -1.633846"/>
      <geometry>
        <mesh filename="package://mirabb_description/meshes/link10_1.stl" scale="0.001 0.001 0.001"/>
      </geometry>
      <material name="generic"/>
    </visual>
    <collision>
      <origin rpy="0 0 0" xyz="-1.770283 0.000662 -1.633846"/>
      <geometry>
        <mesh filename="package://mirabb_description/meshes/link10_1.stl" scale="0.001 0.001 0.001"/>
      </geometry>
    </collision>
  </link>
  <link name="link9_1">
    <inertial>
      <origin rpy="0 0 0" xyz="-0.038754353853061474 -0.00041457716043523976 0.037254020568219914"/>
      <mass value="0.51319675889827"/>
      <inertia ixx="0.009503" ixy="-1.3e-05" ixz="0.001465" iyy="0.01009" iyz="5.5e-05" izz="0.01215"/>
    </inertial>
    <visual>
      <origin rpy="0 0 0" xyz="-1.805783 7.2e-05 -1.830846"/>
      <geometry>
        <mesh filename="package://mirabb_description/meshes/link9_1.stl" scale="0.001 0.001 0.001"/>
      </geometry>
      <material name="paint_metallic_red"/>
    </visual>
    <collision>
      <origin rpy="0 0 0" xyz="-1.805783 7.2e-05 -1.830846"/>
      <geometry>
        <mesh filename="package://mirabb_description/meshes/link9_1.stl" scale="0.001 0.001 0.001"/>
      </geometry>
    </collision>
  </link>
  <link name="link8_1">
    <inertial>
      <origin rpy="0 0 0" xyz="0.025113317898471932 2.9552189966326162e-05 -0.0002673043609695558"/>
      <mass value="0.70679302710691369"/>
      <inertia ixx="0.037858" ixy="2e-06" ixz="-2.1e-05" iyy="0.021317" iyz="-1e-05" izz="0.028823"/>
    </inertial>
    <visual>
      <origin rpy="0 0 0" xyz="-1.803783 0.000662 -1.888846"/>
      <geometry>
        <mesh filename="package://mirabb_description/meshes/link8_1.stl" scale="0.001 0.001 0.001"/>
      </geometry>
      <material name="paint_metallic_silver"/>
    </visual>
    <collision>
      <origin rpy="0 0 0" xyz="-1.803783 0.000662 -1.888846"/>
      <geometry>
        <mesh filename="package://mirabb_description/meshes/link8_1.stl" scale="0.001 0.001 0.001"/>
      </geometry>
    </collision>
  </link>
  <!-- AMR Joints -->
  <joint name="joint_Base_LeftWheel" type="continuous">
    <origin rpy="0 0 0" xyz="-0.000842 -0.331703 0.102346"/>
    <parent link="base_link"/>
    <child link="mir_left_drive_wheel_1"/>
    <axis xyz="-0.0 1.0 -0.0"/>
  </joint>
  <joint name="joint_Base_RightWheel" type="continuous">
    <origin rpy="0 0 0" xyz="-0.000842 0.330477 0.102346"/>
    <parent link="base_link"/>
    <child link="mir_right_drive_wheel_1"/>
    <axis xyz="-0.0 1.0 -0.0"/>
  </joint>
  <joint name="joint_Base_rear_right_caster" type="continuous">
    <origin rpy="0 0 0" xyz="-0.587342 0.324887 0.052346"/>
    <parent link="base_link"/>
    <child link="mir_rear_right_caster_1"/>
    <axis xyz="-0.0 1.0 -0.0"/>
  </joint>
  <joint name="joint_Base_rear_left_caster" type="continuous">
    <origin rpy="0 0 0" xyz="-0.587342 -0.324113 0.052346"/>
    <parent link="base_link"/>
    <child link="mir_rear_left_caster_1"/>
    <axis xyz="-0.0 1.0 -0.0"/>
  </joint>
  <joint name="joint_Base_front_right_caster" type="continuous">
    <origin rpy="0 0 0" xyz="0.492668 0.324887 0.052365"/>
    <parent link="base_link"/>
    <child link="mir_front_right_caster_1"/>
    <axis xyz="-0.0 1.0 -0.0"/>
  </joint>
  <joint name="joint_Base_front_left_caster" type="continuous">
    <origin rpy="0 0 0" xyz="0.492668 -0.324113 0.052365"/>
    <parent link="base_link"/>
    <child link="mir_front_left_caster_1"/>
    <axis xyz="-0.0 1.0 -0.0"/>
  </joint>
  <!-- ============================================================ -->
  <!-- Robot arm Joints  -->
  <joint name="joint0" type="fixed">
    <origin rpy="0 0 0" xyz="0.357783 -0.000662 0.322346"/>
    <parent link="base_link"/>
    <child link="link0_1"/>
  </joint>
  <joint name="joint1" type="continuous">
    <origin rpy="0 0 0" xyz="0.0 0.0 0.1535"/>
    <parent link="link0_1"/>
    <child link="link1_1"/>
    <axis xyz="0.0 0.0 1.0"/>
  </joint>
  <joint name="joint2" type="continuous">
    <origin rpy="0 0 0" xyz="0.175 -0.1225 0.3355"/>
    <parent link="link1_1"/>
    <child link="link2_1"/>
    <axis xyz="0.0 -1.0 0.0"/>
  </joint>
  <joint name="joint3" type="continuous">
    <origin rpy="0 0 0" xyz="0.0 -0.0267 0.9"/>
    <parent link="link2_1"/>
    <child link="link3_1"/>
    <axis xyz="-0.0 1.0 -0.0"/>
  </joint>
  <joint name="joint4" type="continuous">
    <origin rpy="0 0 0" xyz="0.3401 0.1492 0.175"/>
    <parent link="link3_1"/>
    <child link="link4_1"/>
    <axis xyz="1.0 0.0 -0.0"/>
  </joint>
  <joint name="joint5" type="continuous">
    <origin rpy="0 0 0" xyz="0.6199 0.064 0.0"/>
    <parent link="link4_1"/>
    <child link="link5_1"/>
    <axis xyz="0.0 -1.0 0.0"/>
  </joint>
  <joint name="joint6" type="continuous">
    <origin rpy="0 0 0" xyz="0.065 -0.064 0.0"/>
    <parent link="link5_1"/>
    <child link="link6_1"/>
    <axis xyz="1.0 0.0 -0.0"/>
  </joint>
  <!-- ============================================================ -->
  <!-- EOAT Joints -->
  <joint name="joint7" type="fixed">
    <origin rpy="0 0 0" xyz="0.07 0.025 0.043301"/>
    <parent link="link6_1"/>
    <child link="link7_1"/>
  </joint>
  <joint name="joint8" type="revolute">
    <!-- <joint name="joint8" type="fixed"> -->
    <origin rpy="0 0 0" xyz="0.22 -0.105 -0.178801"/>
    <parent link="link7_1"/>
    <child link="link11_1"/>
    <axis xyz="-0.0 1.0 -0.0"/>
    <limit effort="10" lower="-1.5708" upper="0.0" velocity="10"/>
  </joint>
  <joint name="joint9" type="prismatic">
    <!-- <joint name="joint9" type="fixed"> -->
    <origin rpy="0 0 0" xyz="-0.0775 0.08 -0.117"/>
    <parent link="link11_1"/>
    <child link="link10_1"/>
    <axis xyz="-1.0 -0.0 0.0"/>
    <limit effort="10" lower="-0.0" upper="0.07" velocity="10"/>
  </joint>
  <joint name="joint10" type="prismatic">
    <!-- <joint name="joint10" type="fixed"> -->
    <origin rpy="0 0 0" xyz="0.178 -0.02441 -0.098801"/>
    <parent link="link7_1"/>
    <child link="link9_1"/>
    <axis xyz="1.0 0.0 -0.0"/>
    <limit effort="10" lower="0.0" upper="0.07" velocity="10"/>
  </joint>
  <joint name="joint11" type="prismatic">
    <!-- <joint name="joint11" type="fixed"> -->
    <origin rpy="0 0 0" xyz="-0.002 -0.00059 0.058"/>
    <parent link="link9_1"/>
    <child link="link8_1"/>
    <axis xyz="1.0 0.0 -0.0"/>
    <limit effort="10" lower="0.0" upper="0.07" velocity="10"/>
  </joint>
  <!-- ============================================================ -->
</robot>

