<?xml version="1.0" ?>
<!-- =================================================================================== -->
<!-- |    This document was autogenerated by xacro from mirabb_rev2.xacro              | -->
<!-- |    EDITING THIS FILE BY HAND IS NOT RECOMMENDED                                 | -->
<!-- =================================================================================== -->
<robot name="mirabb_rev2">
  <material name="silver_default">
    <color rgba="0.700 0.700 0.700 1.000"/>
  </material>
  <material name="opaque215215215">
    <color rgba="0.8431372549019608 0.8431372549019608 0.8431372549019608 1.0"/>
  </material>
  <material name="opaque25500_1">
    <color rgba="0.14901960784313725 0.3254901960784314 0.9607843137254902 1.0"/>
  </material>
  <material name="opaque25500_1_1">
    <color rgba="0.14901960784313725 0.9607843137254902 0.49019607843137253 1.0"/>
  </material>
  <material name="opaque128128128">
    <color rgba="0.5019607843137255 0.5019607843137255 0.5019607843137255 1.0"/>
  </material>
  <material name="opaque225225225">
    <color rgba="0.8823529411764706 0.8823529411764706 0.8823529411764706 1.0"/>
  </material>
  <material name="opaque636363">
    <color rgba="0.25098039215686274 0.25098039215686274 0.25098039215686274 1.0"/>
  </material>
  <material name="opaque192196191">
    <color rgba="0.7529411764705882 0.7686274509803922 0.7490196078431373 1.0"/>
  </material>
  <material name="opaque25500">
    <color rgba="1.0 0.0 0.0 1.0"/>
  </material>
  <material name="steel_satin">
    <color rgba="0.6274509803921569 0.6274509803921569 0.6274509803921569 1.0"/>
  </material>
  <transmission name="joint_abb_1_to_abb_0_tran">
    <type>transmission_interface/SimpleTransmission</type>
    <joint name="joint_abb_1_to_abb_0">
      <hardwareInterface>hardware_interface/PositionJointInterface</hardwareInterface>
    </joint>
    <actuator name="joint_abb_1_to_abb_0_actr">
      <hardwareInterface>hardware_interface/PositionJointInterface</hardwareInterface>
      <mechanicalReduction>1</mechanicalReduction>
    </actuator>
  </transmission>
  <transmission name="joint_abb_2_to_abb_1_tran">
    <type>transmission_interface/SimpleTransmission</type>
    <joint name="joint_abb_2_to_abb_1">
      <hardwareInterface>hardware_interface/PositionJointInterface</hardwareInterface>
    </joint>
    <actuator name="joint_abb_2_to_abb_1_actr">
      <hardwareInterface>hardware_interface/PositionJointInterface</hardwareInterface>
      <mechanicalReduction>1</mechanicalReduction>
    </actuator>
  </transmission>
  <transmission name="joint_abb_3_to_abb_2_tran">
    <type>transmission_interface/SimpleTransmission</type>
    <joint name="joint_abb_3_to_abb_2">
      <hardwareInterface>hardware_interface/PositionJointInterface</hardwareInterface>
    </joint>
    <actuator name="joint_abb_3_to_abb_2_actr">
      <hardwareInterface>hardware_interface/PositionJointInterface</hardwareInterface>
      <mechanicalReduction>1</mechanicalReduction>
    </actuator>
  </transmission>
  <transmission name="joint_abb_4_to_abb_3_tran">
    <type>transmission_interface/SimpleTransmission</type>
    <joint name="joint_abb_4_to_abb_3">
      <hardwareInterface>hardware_interface/PositionJointInterface</hardwareInterface>
    </joint>
    <actuator name="joint_abb_4_to_abb_3_actr">
      <hardwareInterface>hardware_interface/PositionJointInterface</hardwareInterface>
      <mechanicalReduction>1</mechanicalReduction>
    </actuator>
  </transmission>
  <transmission name="joint_abb_5_to_abb_4_tran">
    <type>transmission_interface/SimpleTransmission</type>
    <joint name="joint_abb_5_to_abb_4">
      <hardwareInterface>hardware_interface/PositionJointInterface</hardwareInterface>
    </joint>
    <actuator name="joint_abb_5_to_abb_4_actr">
      <hardwareInterface>hardware_interface/PositionJointInterface</hardwareInterface>
      <mechanicalReduction>1</mechanicalReduction>
    </actuator>
  </transmission>
  <transmission name="joint_abb_6_to_abb_5_tran">
    <type>transmission_interface/SimpleTransmission</type>
    <joint name="joint_abb_6_to_abb_5">
      <hardwareInterface>hardware_interface/PositionJointInterface</hardwareInterface>
    </joint>
    <actuator name="joint_abb_6_to_abb_5_actr">
      <hardwareInterface>hardware_interface/PositionJointInterface</hardwareInterface>
      <mechanicalReduction>1</mechanicalReduction>
    </actuator>
  </transmission>
  <!-- <transmission name="joint_abb_1_to_abb_0_tran">
  <type>transmission_interface/SimpleTransmission</type>
  <joint name="joint_abb_1_to_abb_0">
    <hardwareInterface>hardware_interface/EffortJointInterface</hardwareInterface>
  </joint>
  <actuator name="joint_abb_1_to_abb_0_actr">
    <hardwareInterface>hardware_interface/EffortJointInterface</hardwareInterface>
    <mechanicalReduction>1</mechanicalReduction>
  </actuator>
</transmission>
 
<transmission name="joint_abb_2_to_abb_1_tran">
  <type>transmission_interface/SimpleTransmission</type>
  <joint name="joint_abb_2_to_abb_1">
    <hardwareInterface>hardware_interface/EffortJointInterface</hardwareInterface>
  </joint>
  <actuator name="joint_abb_2_to_abb_1_actr">
    <hardwareInterface>hardware_interface/EffortJointInterface</hardwareInterface>
    <mechanicalReduction>1</mechanicalReduction>
  </actuator>
</transmission>

<transmission name="joint_abb_3_to_abb_2_tran">
  <type>transmission_interface/SimpleTransmission</type>
  <joint name="joint_abb_3_to_abb_2">
    <hardwareInterface>hardware_interface/EffortJointInterface</hardwareInterface>
  </joint>
  <actuator name="joint_abb_3_to_abb_2_actr">
    <hardwareInterface>hardware_interface/EffortJointInterface</hardwareInterface>
    <mechanicalReduction>1</mechanicalReduction>
  </actuator>
</transmission>

<transmission name="joint_abb_4_to_abb_3_tran">
  <type>transmission_interface/SimpleTransmission</type>
  <joint name="joint_abb_4_to_abb_3">
    <hardwareInterface>hardware_interface/EffortJointInterface</hardwareInterface>
  </joint>
  <actuator name="joint_abb_4_to_abb_3_actr">
    <hardwareInterface>hardware_interface/EffortJointInterface</hardwareInterface>
    <mechanicalReduction>1</mechanicalReduction>
  </actuator>
</transmission>

<transmission name="joint_abb_5_to_abb_4_tran">
  <type>transmission_interface/SimpleTransmission</type>
  <joint name="joint_abb_5_to_abb_4">
    <hardwareInterface>hardware_interface/EffortJointInterface</hardwareInterface>
  </joint>
  <actuator name="joint_abb_5_to_abb_4_actr">
    <hardwareInterface>hardware_interface/EffortJointInterface</hardwareInterface>
    <mechanicalReduction>1</mechanicalReduction>
  </actuator>
</transmission>

<transmission name="joint_abb_6_to_abb_5_tran">
  <type>transmission_interface/SimpleTransmission</type>
  <joint name="joint_abb_6_to_abb_5">
    <hardwareInterface>hardware_interface/EffortJointInterface</hardwareInterface>
  </joint>
  <actuator name="joint_abb_6_to_abb_5_actr">
    <hardwareInterface>hardware_interface/EffortJointInterface</hardwareInterface>
    <mechanicalReduction>1</mechanicalReduction>
  </actuator>
</transmission> -->
  <gazebo reference="base_link">
    <material>Gazebo/Grey</material>
  </gazebo>
  <gazebo reference="battery_pack_1">
    <material>Gazebo/Grey</material>
  </gazebo>
  <gazebo reference="IRC5_1">
    <material>Gazebo/Grey</material>
  </gazebo>
  <gazebo reference="rear_left_caster_1">
    <material>Gazebo/Yellow</material>
  </gazebo>
  <gazebo reference="rear_right_caster_1">
    <material>Gazebo/Yellow</material>
  </gazebo>
  <gazebo reference="front_right_caster_1">
    <material>Gazebo/Yellow</material>
  </gazebo>
  <gazebo reference="front_left_caster_1">
    <material>Gazebo/Yellow</material>
  </gazebo>
  <gazebo reference="right_drive_wheel_1">
    <material>Gazebo/Green</material>
  </gazebo>
  <gazebo reference="left_drive_wheel_1">
    <material>Gazebo/Green</material>
  </gazebo>
  <gazebo reference="rear_lidar_1">
    <material>Gazebo/Blue</material>
  </gazebo>
  <gazebo reference="front_lidar_1">
    <material>Gazebo/Blue</material>
  </gazebo>
  <gazebo reference="abb_link_0_1">
    <material>Gazebo/DarkYellow</material>
  </gazebo>
  <gazebo reference="abb_link_1_1">
    <material>Gazebo/DarkYellow</material>
  </gazebo>
  <gazebo reference="abb_link_2_1">
    <material>Gazebo/DarkYellow</material>
  </gazebo>
  <gazebo reference="abb_link_3_1">
    <material>Gazebo/DarkYellow</material>
  </gazebo>
  <gazebo reference="abb_link_4_1">
    <material>Gazebo/DarkYellow</material>
  </gazebo>
  <gazebo reference="abb_link_5_1">
    <material>Gazebo/DarkYellow</material>
  </gazebo>
  <gazebo reference="abb_link_6_1">
    <material>Gazebo/DarkYellow</material>
  </gazebo>
   --&gt;


  <gazebo reference="base_link">
    <mu1>0.2</mu1>
    <mu2>0.2</mu2>
    <selfCollide>true</selfCollide>
    <gravity>true</gravity>
  </gazebo>
  <gazebo reference="battery_pack_1">
    <mu1>0.2</mu1>
    <mu2>0.2</mu2>
    <selfCollide>true</selfCollide>
  </gazebo>
  <gazebo reference="IRC5_1">
    <mu1>0.2</mu1>
    <mu2>0.2</mu2>
    <selfCollide>true</selfCollide>
  </gazebo>
  <gazebo reference="rear_left_caster_1">
    <mu1>0.1</mu1>
    <mu2>0.1</mu2>
    <selfCollide>true</selfCollide>
  </gazebo>
  <gazebo reference="rear_right_caster_1">
    <mu1>0.1</mu1>
    <mu2>0.1</mu2>
    <selfCollide>true</selfCollide>
  </gazebo>
  <gazebo reference="front_right_caster_1">
    <mu1>0.1</mu1>
    <mu2>0.1</mu2>
    <selfCollide>true</selfCollide>
  </gazebo>
  <gazebo reference="front_left_caster_1">
    <mu1>0.1</mu1>
    <mu2>0.1</mu2>
    <selfCollide>true</selfCollide>
  </gazebo>
  <gazebo reference="right_drive_wheel_1">
    <mu1>200.0</mu1>
    <mu2>200.0</mu2>
    <selfCollide>true</selfCollide>
  </gazebo>
  <gazebo reference="left_drive_wheel_1">
    <mu1>200.0</mu1>
    <mu2>200.0</mu2>
    <selfCollide>true</selfCollide>
  </gazebo>
  <gazebo reference="rear_lidar_1">
    <mu1>0.2</mu1>
    <mu2>0.2</mu2>
    <selfCollide>true</selfCollide>
  </gazebo>
  <gazebo reference="front_lidar_1">
    <mu1>0.2</mu1>
    <mu2>0.2</mu2>
    <selfCollide>true</selfCollide>
  </gazebo>
  <gazebo reference="abb_link_0_1">
    <mu1>0.2</mu1>
    <mu2>0.2</mu2>
    <selfCollide>true</selfCollide>
  </gazebo>
  <gazebo reference="abb_link_1_1">
    <mu1>0.2</mu1>
    <mu2>0.2</mu2>
    <selfCollide>true</selfCollide>
  </gazebo>
  <gazebo reference="abb_link_2_1">
    <mu1>0.2</mu1>
    <mu2>0.2</mu2>
    <selfCollide>true</selfCollide>
  </gazebo>
  <gazebo reference="abb_link_3_1">
    <mu1>0.2</mu1>
    <mu2>0.2</mu2>
    <selfCollide>true</selfCollide>
  </gazebo>
  <gazebo reference="abb_link_4_1">
    <mu1>0.2</mu1>
    <mu2>0.2</mu2>
    <selfCollide>true</selfCollide>
  </gazebo>
  <gazebo reference="abb_link_5_1">
    <mu1>0.2</mu1>
    <mu2>0.2</mu2>
    <selfCollide>true</selfCollide>
  </gazebo>
  <gazebo reference="abb_link_6_1">
    <mu1>0.2</mu1>
    <mu2>0.2</mu2>
    <selfCollide>true</selfCollide>
  </gazebo>
  <!-- <gazebo>
  <plugin name="control" filename="libgazebo_ros_control.so"/>
</gazebo> -->
  <!-- <<<<<<<<<<<<<<<<<<<<<<<<<<<<<<<< ros_control  >>>>>>>>>>>>>>>>>>>>>>>>>>>>>>>>>>>>>> -->
  <gazebo>
    <plugin filename="libgazebo_ros_control.so" name="gazebo_ros_control">
      <robotNamespace>/mirabb_rev2</robotNamespace>
      <robotSimType>gazebo_ros_control/DefaultRobotHWSim</robotSimType>
    </plugin>
  </gazebo>
  <!-- <<<<<<<<<<<<<<<<<<<<<<<<<<<<<<<< laser >>>>>>>>>>>>>>>>>>>>>>>>>>>>>>>>>>>>>> -->
  <!-- front laser-->
  <!-- hokuyo -->
  <gazebo reference="front_lidar_1">
    <sensor name="front_hokuyo_sensor" type="ray">
      <pose>0 0 0 0 0 0</pose>
      <visualize>true</visualize>
      <update_rate>10</update_rate>
      <ray>
        <scan>
          <horizontal>
            <samples>720</samples>
            <resolution>1</resolution>
            <min_angle>-1.5708</min_angle>
            <max_angle>3.14159</max_angle>
          </horizontal>
        </scan>
        <range>
          <min>0.10</min>
          <max>30.0</max>
          <resolution>0.01</resolution>
        </range>
        <noise>
          <type>gaussian</type>
          <!-- Noise parameters based on published spec for Hokuyo laser
               achieving "+-30mm" accuracy at range < 10m.  A mean of 0.0m and
               stddev of 0.01m will put 99.7% of samples within 0.03m of the true
               reading. -->
          <mean>0.0</mean>
          <stddev>0.01</stddev>
        </noise>
      </ray>
      <plugin filename="libgazebo_ros_laser.so" name="gazebo_ros_head_hokuyo_controller">
        <topicName>/mirabb_rev2/laser/front_scan</topicName>
        <frameName>front_lidar_1</frameName>
      </plugin>
    </sensor>
  </gazebo>
  <!-- rear laser-->
  <!-- hokuyo -->
  <gazebo reference="rear_lidar_1">
    <sensor name="rear_hokuyo_sensor" type="ray">
      <pose>0 0 0 0 0 0</pose>
      <visualize>true</visualize>
      <update_rate>10</update_rate>
      <ray>
        <scan>
          <horizontal>
            <samples>720</samples>
            <resolution>1</resolution>
            <min_angle>-4.71239</min_angle>
            <max_angle>0</max_angle>
          </horizontal>
        </scan>
        <range>
          <min>0.10</min>
          <max>30.0</max>
          <resolution>0.01</resolution>
        </range>
        <noise>
          <type>gaussian</type>
          <!-- Noise parameters based on published spec for Hokuyo laser
               achieving "+-30mm" accuracy at range < 10m.  A mean of 0.0m and
               stddev of 0.01m will put 99.7% of samples within 0.03m of the true
               reading. -->
          <mean>0.0</mean>
          <stddev>0.01</stddev>
        </noise>
      </ray>
      <plugin filename="libgazebo_ros_laser.so" name="gazebo_ros_head_hokuyo_controller">
        <topicName>/mirabb_rev2/laser/rear_scan</topicName>
        <frameName>rear_lidar_1</frameName>
      </plugin>
    </sensor>
  </gazebo>
  <!-- <<<<<<<<<<<<<<<<<<<<<<<<<<<<<<<<<<<<< >>>>>>>>>>>>>>>>>>>>>>>>>>>>>>>>>...>>>>>>>> -->
  <!-- <<<<<<<<<<<<<<<<<<<<<<<<<<<<<<<< diff drive >>>>>>>>>>>>>>>>>>>>>>>>>>>>>>>>>>>>>> -->
  <gazebo>
    <plugin filename="libgazebo_ros_diff_drive.so" name="differential_drive_controller">
      <!-- Plugin update rate in Hz -->
      <updateRate>50</updateRate>
      <!-- Name of left joint, defaults to `left_joint` -->
      <leftJoint>joint_left_drive_wheel_to_base</leftJoint>
      <!-- Name of right joint, defaults to `right_joint` -->
      <rightJoint>joint_right_drive_wheel_to_base</rightJoint>
      <!-- Wheel acceleration, in rad/s^2, defaults to 0.0 rad/s^2 -->
      <wheelAcceleration>75.0</wheelAcceleration>
      <!-- Maximum torque which the wheels can produce, in Nm, defaults to 5 Nm -->
      <wheelTorque>500</wheelTorque>
      <!-- Topic to receive geometry_msgs/Twist message commands, defaults to `cmd_vel` -->
      <commandTopic>cmd_vel</commandTopic>
      <!-- Topic to publish nav_msgs/Odometry messages, defaults to `odom` -->
      <odometryTopic>odom</odometryTopic>
      <!-- Odometry frame, defaults to `odom` -->
      <odometryFrame>odom</odometryFrame>
      <!-- Robot frame to calculate odometry from, defaults to `base_footprint` -->
      <robotBaseFrame>base_link</robotBaseFrame>
      <!-- Odometry source, 0 for ENCODER, 1 for WORLD, defaults to WORLD -->
      <odometrySource>1</odometrySource>
      <!-- Set to true to publish transforms for the wheel links, defaults to false -->
      <publishWheelTF>true</publishWheelTF>
      <!-- Set to true to publish transforms for the odometry, defaults to true -->
      <publishOdom>true</publishOdom>
      <!-- Set to true to publish sensor_msgs/JointState on /joint_states for the wheel joints, defaults to false -->
      <publishWheelJointState>true</publishWheelJointState>
      <!-- Set to true to swap right and left wheels, defaults to true -->
      <legacyMode>false</legacyMode>
    </plugin>
  </gazebo>
  <!-- <<<<<<<<<<<<<<<<<<<<<<<<<<<<<<<< 2d Camera >>>>>>>>>>>>>>>>>>>>>>>>>>>>>>>>>>>>>> -->
  <!-- camera  -->
  <gazebo reference="camera">
    <sensor name="camera" type="camera">
      <update_rate>30.0</update_rate>
      <camera name="2d_camera">
        <horizontal_fov>1.3962634</horizontal_fov>
        <image>
          <width>800</width>
          <height>800</height>
          <format>R8G8B8</format>
        </image>
        <clip>
          <near>0.02</near>
          <far>300</far>
        </clip>
        <noise>
          <type>gaussian</type>
          <!-- Noise is sampled independently per pixel on each frame.
               That pixel's noise value is added to each of its color
               channels, which at that point lie in the range [0,1]. -->
          <mean>0.0</mean>
          <stddev>0.007</stddev>
        </noise>
      </camera>
      <plugin filename="libgazebo_ros_camera.so" name="camera_controller">
        <alwaysOn>true</alwaysOn>
        <updateRate>30.0</updateRate>
        <cameraName>mirabb/camera</cameraName>
        <imageTopicName>image_raw</imageTopicName>
        <cameraInfoTopicName>camera_info</cameraInfoTopicName>
        <frameName>camera</frameName>
        <hackBaseline>0.07</hackBaseline>
        <distortionK1>0.0</distortionK1>
        <distortionK2>0.0</distortionK2>
        <distortionK3>0.0</distortionK3>
        <distortionT1>0.0</distortionT1>
        <distortionT2>0.0</distortionT2>
      </plugin>
    </sensor>
  </gazebo>
  <!-- <<<<<<<<<<<<<<<<<<<<<<<<<<<<<<<<<<<<< >>>>>>>>>>>>>>>>>>>>>>>>>>>>>>>>>>>>>>>>>>>> -->
  <!-- ======================================== links ========================================= -->
  <link name="base_link">
    <inertial>
      <origin rpy="0 0 0" xyz="-0.005052905851329634 0.0009237993595675954 0.19509462972372268"/>
      <mass value="731.1841440414972"/>
      <inertia ixx="44.903938" ixy="-0.104753" ixz="0.049526" iyy="101.343685" iyz="0.079845" izz="136.36036"/>
    </inertial>
    <visual>
      <origin rpy="0 0 0" xyz="0 0 0"/>
      <geometry>
        <mesh filename="package://mirabb_rev2_description/meshes/base_link.stl" scale="0.001 0.001 0.001"/>
      </geometry>
      <material name="opaque636363"/>
    </visual>
    <collision>
      <origin rpy="0 0 0" xyz="0 0 0"/>
      <geometry>
        <mesh filename="package://mirabb_rev2_description/meshes/base_link.stl" scale="0.001 0.001 0.001"/>
      </geometry>
    </collision>
  </link>
  <link name="battery_pack_1">
    <inertial>
      <origin rpy="0 0 0" xyz="0.3382791205796017 -0.15021271924052587 0.32461061393101465"/>
      <mass value="110.65048122246903"/>
      <inertia ixx="47.958217" ixy="0.0" ixz="0.0" iyy="82.770779" iyz="0.03336" izz="52.993229"/>
    </inertial>
    <visual>
      <origin rpy="0 0 0" xyz="0.671632 -0.456901 -0.333225"/>
      <geometry>
        <mesh filename="package://mirabb_rev2_description/meshes/battery_pack_1.stl" scale="0.001 0.001 0.001"/>
      </geometry>
      <material name="steel_satin"/>
    </visual>
    <collision>
      <origin rpy="0 0 0" xyz="0.671632 -0.456901 -0.333225"/>
      <geometry>
        <mesh filename="package://mirabb_rev2_description/meshes/battery_pack_1.stl" scale="0.001 0.001 0.001"/>
      </geometry>
    </collision>
  </link>
  <link name="IRC5_1">
    <inertial>
      <origin rpy="0 0 0" xyz="0.34747421633122205 0.2748966687089476 0.38207835577474003"/>
      <mass value="165.9374645529373"/>
      <inertia ixx="83.575164" ixy="0.317379" ixz="-0.083214" iyy="108.519954" iyz="3.527308" izz="110.829977"/>
    </inertial>
    <visual>
      <origin rpy="0 0 0" xyz="0.671632 0.408099 -0.333225"/>
      <geometry>
        <mesh filename="package://mirabb_rev2_description/meshes/IRC5_1.stl" scale="0.001 0.001 0.001"/>
      </geometry>
      <material name="opaque192196191"/>
    </visual>
    <collision>
      <origin rpy="0 0 0" xyz="0.671632 0.408099 -0.333225"/>
      <geometry>
        <mesh filename="package://mirabb_rev2_description/meshes/IRC5_1.stl" scale="0.001 0.001 0.001"/>
      </geometry>
    </collision>
  </link>
  <link name="rear_left_caster_1">
    <inertial>
      <origin rpy="0 0 0" xyz="1.2700628260198243e-07 0.040000141287039714 -1.4280461667348643e-08"/>
      <mass value="3.28635082694758"/>
      <inertia ixx="0.00407" ixy="-0.0" ixz="-0.0" iyy="0.004808" iyz="-0.0" izz="0.00407"/>
    </inertial>
    <visual>
      <origin rpy="0 0 0" xyz="0.583132 0.362599 -0.058225"/>
      <geometry>
        <mesh filename="package://mirabb_rev2_description/meshes/rear_left_caster_1.stl" scale="0.001 0.001 0.001"/>
      </geometry>
      <material name="opaque25500_1"/>
    </visual>
    <collision>
      <origin rpy="0 0 0" xyz="0.583132 0.362599 -0.058225"/>
      <geometry>
        <mesh filename="package://mirabb_rev2_description/meshes/rear_left_caster_1.stl" scale="0.001 0.001 0.001"/>
      </geometry>
    </collision>
  </link>
  <link name="rear_right_caster_1">
    <inertial>
      <origin rpy="0 0 0" xyz="1.2700613527538707e-07 -0.03999985871297529 -1.4280526317023146e-08"/>
      <mass value="2.834030293976285"/>
      <inertia ixx="0.00334" ixy="-0.0" ixz="-0.0" iyy="0.003822" iyz="-0.0" izz="0.00334"/>
    </inertial>
    <visual>
      <origin rpy="0 0 0" xyz="0.583132 -0.366401 -0.058225"/>
      <geometry>
        <mesh filename="package://mirabb_rev2_description/meshes/rear_right_caster_1.stl" scale="0.001 0.001 0.001"/>
      </geometry>
      <material name="opaque25500_1"/>
    </visual>
    <collision>
      <origin rpy="0 0 0" xyz="0.583132 -0.366401 -0.058225"/>
      <geometry>
        <mesh filename="package://mirabb_rev2_description/meshes/rear_right_caster_1.stl" scale="0.001 0.001 0.001"/>
      </geometry>
    </collision>
  </link>
  <link name="front_right_caster_1">
    <inertial>
      <origin rpy="0 0 0" xyz="1.520973808566417e-07 -0.03999985871272993 -2.5129112466576453e-07"/>
      <mass value="3.2863508269475643"/>
      <inertia ixx="0.00407" ixy="-0.0" ixz="-0.0" iyy="0.004808" iyz="-0.0" izz="0.00407"/>
    </inertial>
    <visual>
      <origin rpy="0 0 0" xyz="-0.496877 -0.366401 -0.058244"/>
      <geometry>
        <mesh filename="package://mirabb_rev2_description/meshes/front_right_caster_1.stl" scale="0.001 0.001 0.001"/>
      </geometry>
      <material name="opaque25500_1"/>
    </visual>
    <collision>
      <origin rpy="0 0 0" xyz="-0.496877 -0.366401 -0.058244"/>
      <geometry>
        <mesh filename="package://mirabb_rev2_description/meshes/front_right_caster_1.stl" scale="0.001 0.001 0.001"/>
      </geometry>
    </collision>
  </link>
  <link name="front_left_caster_1">
    <inertial>
      <origin rpy="0 0 0" xyz="1.5209757575629368e-07 0.040000141287288626 -2.5129119475553185e-07"/>
      <mass value="3.2863508269475803"/>
      <inertia ixx="0.00407" ixy="-0.0" ixz="-0.0" iyy="0.004808" iyz="-0.0" izz="0.00407"/>
    </inertial>
    <visual>
      <origin rpy="0 0 0" xyz="-0.496877 0.362599 -0.058244"/>
      <geometry>
        <mesh filename="package://mirabb_rev2_description/meshes/front_left_caster_1.stl" scale="0.001 0.001 0.001"/>
      </geometry>
      <material name="opaque25500_1"/>
    </visual>
    <collision>
      <origin rpy="0 0 0" xyz="-0.496877 0.362599 -0.058244"/>
      <geometry>
        <mesh filename="package://mirabb_rev2_description/meshes/front_left_caster_1.stl" scale="0.001 0.001 0.001"/>
      </geometry>
    </collision>
  </link>
  <link name="right_drive_wheel_1">
    <inertial>
      <origin rpy="0 0 0" xyz="3.9465326454784025e-07 -0.02500185564569668 -6.506273999187795e-06"/>
      <mass value="5.294052840904851"/>
      <inertia ixx="0.021658" ixy="0.0" ixz="0.0" iyy="0.041149" iyz="-1e-06" izz="0.021656"/>
    </inertial>
    <visual>
      <origin rpy="0 0 0" xyz="-0.003368 -0.356991 -0.108225"/>
      <geometry>
        <mesh filename="package://mirabb_rev2_description/meshes/right_drive_wheel_1.stl" scale="0.001 0.001 0.001"/>
      </geometry>
      <material name="opaque25500_1_1"/>
    </visual>
    <collision>
      <origin rpy="0 0 0" xyz="-0.003368 -0.356991 -0.108225"/>
      <geometry>
        <mesh filename="package://mirabb_rev2_description/meshes/right_drive_wheel_1.stl" scale="0.001 0.001 0.001"/>
      </geometry>
    </collision>
  </link>
  <link name="left_drive_wheel_1">
    <inertial>
      <origin rpy="0 0 0" xyz="-1.4064040030226793e-07 0.02500213822004227 -6.506273913825522e-06"/>
      <mass value="5.294052840904075"/>
      <inertia ixx="0.021658" ixy="0.0" ixz="-0.0" iyy="0.041149" iyz="1e-06" izz="0.021656"/>
    </inertial>
    <visual>
      <origin rpy="0 0 0" xyz="-0.003368 0.355189 -0.108225"/>
      <geometry>
        <mesh filename="package://mirabb_rev2_description/meshes/left_drive_wheel_1.stl" scale="0.001 0.001 0.001"/>
      </geometry>
      <material name="opaque25500_1_1"/>
    </visual>
    <collision>
      <origin rpy="0 0 0" xyz="-0.003368 0.355189 -0.108225"/>
      <geometry>
        <mesh filename="package://mirabb_rev2_description/meshes/left_drive_wheel_1.stl" scale="0.001 0.001 0.001"/>
      </geometry>
    </collision>
  </link>
  <link name="rear_lidar_1">
    <inertial>
      <origin rpy="0 0 0" xyz="0.0016905374305226095 0.00025113064620507775 -0.007627880367609197"/>
      <mass value="0.6451222059189863"/>
      <inertia ixx="0.000317" ixy="6e-06" ixz="1e-06" iyy="0.000277" iyz="0.0" izz="0.00057"/>
    </inertial>
    <visual>
      <origin rpy="0 0 0" xyz="0.586482 0.368099 -0.203225"/>
      <geometry>
        <mesh filename="package://mirabb_rev2_description/meshes/rear_lidar_1.stl" scale="0.001 0.001 0.001"/>
      </geometry>
      <material name="opaque25500"/>
    </visual>
    <collision>
      <origin rpy="0 0 0" xyz="0.586482 0.368099 -0.203225"/>
      <geometry>
        <mesh filename="package://mirabb_rev2_description/meshes/rear_lidar_1.stl" scale="0.001 0.001 0.001"/>
      </geometry>
    </collision>
  </link>
  <link name="front_lidar_1">
    <inertial>
      <origin rpy="0 0 0" xyz="0.0002508766141638974 -0.0016905088880322938 -0.007627880367266859"/>
      <mass value="0.645122205919022"/>
      <inertia ixx="0.000277" ixy="-6e-06" ixz="0.0" iyy="0.000317" iyz="-1e-06" izz="0.00057"/>
    </inertial>
    <visual>
      <origin rpy="0 0 0" xyz="-0.593218 -0.371901 -0.203225"/>
      <geometry>
        <mesh filename="package://mirabb_rev2_description/meshes/front_lidar_1.stl" scale="0.001 0.001 0.001"/>
      </geometry>
      <material name="opaque25500"/>
    </visual>
    <collision>
      <origin rpy="0 0 0" xyz="-0.593218 -0.371901 -0.203225"/>
      <geometry>
        <mesh filename="package://mirabb_rev2_description/meshes/front_lidar_1.stl" scale="0.001 0.001 0.001"/>
      </geometry>
    </collision>
  </link>
  <link name="abb_link_0_1">
    <inertial>
      <origin rpy="0 0 0" xyz="-0.09119342807389941 0.0003632766664137069 0.061964520523223876"/>
      <mass value="2.3771328449710649"/>
      <inertia ixx="3.322456" ixy="0.030784" ixz="0.455197" iyy="6.746895" iyz="0.001141" izz="9.112071"/>
    </inertial>
    <visual>
      <origin rpy="0 0 0" xyz="-0.45 -0.0 -0.323225"/>
      <geometry>
        <mesh filename="package://mirabb_rev2_description/meshes/abb_link_0_1.stl" scale="0.001 0.001 0.001"/>
      </geometry>
      <material name="opaque215215215"/>
    </visual>
    <collision>
      <origin rpy="0 0 0" xyz="-0.45 -0.0 -0.323225"/>
      <geometry>
        <mesh filename="package://mirabb_rev2_description/meshes/abb_link_0_1.stl" scale="0.001 0.001 0.001"/>
      </geometry>
    </collision>
  </link>
  <link name="abb_link_1_1">
    <inertial>
      <origin rpy="0 0 0" xyz="0.07703822885743022 0.024690140056604287 0.2406984296125637"/>
      <mass value="3.329466873877731"/>
      <inertia ixx="8.732818" ixy="-0.760548" ixz="-2.349545" iyy="11.378245" iyz="-0.812185" izz="9.105966"/>
    </inertial>
    <visual>
      <origin rpy="0 0 0" xyz="-0.45 -0.0 -0.462225"/>
      <geometry>
        <mesh filename="package://mirabb_rev2_description/meshes/abb_link_1_1.stl" scale="0.001 0.001 0.001"/>
      </geometry>
      <material name="opaque215215215"/>
    </visual>
    <collision>
      <origin rpy="0 0 0" xyz="-0.45 -0.0 -0.462225"/>
      <geometry>
        <mesh filename="package://mirabb_rev2_description/meshes/abb_link_1_1.stl" scale="0.001 0.001 0.001"/>
      </geometry>
    </collision>
  </link>
  <link name="abb_link_2_1">
    <inertial>
      <origin rpy="0 0 0" xyz="1.001368435393779e-06 -0.047559072898264526 0.4878264798203047"/>
      <mass value="2.690302108058418"/>
      <inertia ixx="29.355719" ixy="-0.000106" ixz="0.001275" iyy="30.105846" iyz="0.846949" izz="1.557161"/>
    </inertial>
    <visual>
      <origin rpy="0 0 0" xyz="-0.625 0.1225 -0.797725"/>
      <geometry>
        <mesh filename="package://mirabb_rev2_description/meshes/abb_link_2_1.stl" scale="0.001 0.001 0.001"/>
      </geometry>
      <material name="opaque215215215"/>
    </visual>
    <collision>
      <origin rpy="0 0 0" xyz="-0.625 0.1225 -0.797725"/>
      <geometry>
        <mesh filename="package://mirabb_rev2_description/meshes/abb_link_2_1.stl" scale="0.001 0.001 0.001"/>
      </geometry>
    </collision>
  </link>
  <link name="abb_link_3_1">
    <inertial>
      <origin rpy="0 0 0" xyz="0.0407124699633189 0.19846613138023458 0.1187619783970777"/>
      <mass value="0.04971415915851"/>
      <inertia ixx="8.893897" ixy="0.577245" ixz="-0.921456" iyy="10.88791" iyz="-0.110794" izz="8.946802"/>
    </inertial>
    <visual>
      <origin rpy="0 0 0" xyz="-0.625 0.1492 -1.892725"/>
      <geometry>
        <mesh filename="package://mirabb_rev2_description/meshes/abb_link_3_1.stl" scale="0.001 0.001 0.001"/>
      </geometry>
      <material name="opaque215215215"/>
    </visual>
    <collision>
      <origin rpy="0 0 0" xyz="-0.625 0.1492 -1.892725"/>
      <geometry>
        <mesh filename="package://mirabb_rev2_description/meshes/abb_link_3_1.stl" scale="0.001 0.001 0.001"/>
      </geometry>
    </collision>
  </link>
  <link name="abb_link_4_1">
    <inertial>
      <origin rpy="0 0 0" xyz="0.4981656538583473 0.0008083116472092178 0.00023536472418461685"/>
      <mass value="0.07381747991609211"/>
      <inertia ixx="0.158364" ixy="-0.02267" ixz="-0.003699" iyy="6.956835" iyz="0.000119" izz="6.981902"/>
    </inertial>
    <visual>
      <origin rpy="0 0 0" xyz="-0.9651 -0.0 -2.067725"/>
      <geometry>
        <mesh filename="package://mirabb_rev2_description/meshes/abb_link_4_1.stl" scale="0.001 0.001 0.001"/>
      </geometry>
      <material name="opaque215215215"/>
    </visual>
    <collision>
      <origin rpy="0 0 0" xyz="-0.9651 -0.0 -2.067725"/>
      <geometry>
        <mesh filename="package://mirabb_rev2_description/meshes/abb_link_4_1.stl" scale="0.001 0.001 0.001"/>
      </geometry>
    </collision>
  </link>
  <link name="abb_link_5_1">
    <inertial>
      <origin rpy="0 0 0" xyz="0.0002420230798942935 0.020477376265846853 0.0008926528509860532"/>
      <mass value="0.002908310329961815"/>
      <inertia ixx="0.002454" ixy="2e-06" ixz="4.7e-05" iyy="0.004276" iyz="-2e-06" izz="0.002692"/>
    </inertial>
    <visual>
      <origin rpy="0 0 0" xyz="-1.8555 0.0205 -2.067725"/>
      <geometry>
        <mesh filename="package://mirabb_rev2_description/meshes/abb_link_5_1.stl" scale="0.001 0.001 0.001"/>
      </geometry>
      <material name="opaque225225225"/>
    </visual>
    <collision>
      <origin rpy="0 0 0" xyz="-1.8555 0.0205 -2.067725"/>
      <geometry>
        <mesh filename="package://mirabb_rev2_description/meshes/abb_link_5_1.stl" scale="0.001 0.001 0.001"/>
      </geometry>
    </collision>
  </link>
  <link name="abb_link_6_1">
    <inertial>
      <origin rpy="0 0 0" xyz="0.021308530149013682 1.8171855728165108e-09 -0.00018066012267503595"/>
      <mass value="0.00378252209682352"/>
      <inertia ixx="0.000148" ixy="0.0" ixz="0.0" iyy="0.000107" iyz="0.0" izz="0.000109"/>
    </inertial>
    <visual>
      <origin rpy="0 0 0" xyz="-1.9065 -0.0 -2.067725"/>
      <geometry>
        <mesh filename="package://mirabb_rev2_description/meshes/abb_link_6_1.stl" scale="0.001 0.001 0.001"/>
      </geometry>
      <material name="opaque128128128"/>
    </visual>
    <collision>
      <origin rpy="0 0 0" xyz="-1.9065 -0.0 -2.067725"/>
      <geometry>
        <mesh filename="package://mirabb_rev2_description/meshes/abb_link_6_1.stl" scale="0.001 0.001 0.001"/>
      </geometry>
    </collision>
  </link>
  <!-- camera -->
  <link name="camera">
    <collision>
      <origin rpy="0 0 0" xyz="0.050 0.10 0.050"/>
      <geometry>
        <box size="0.1 0.200 0.100"/>
      </geometry>
    </collision>
    <visual>
      <origin rpy="0 0 0" xyz="0.050 0.10 0.050"/>
      <geometry>
        <box size="0.1 0.200 0.100"/>
      </geometry>
      <material name="opaque25500"/>
    </visual>
    <inertial>
      <origin rpy="0 0 0" xyz="0.050 0.10 0.050"/>
      <mass value="1"/>
      <inertia ixx="1.0" ixy="0.0" ixz="0.0" iyy="1.0" iyz="0.0" izz="1.0"/>
    </inertial>
  </link>
  <!-- ======================================== ===== ========================================= -->
  <!-- joints -->
  <joint name="joint_battery_to_base" type="fixed">
    <origin rpy="0 0 0" xyz="-0.671632 0.456901 0.333225"/>
    <parent link="base_link"/>
    <child link="battery_pack_1"/>
  </joint>
  <joint name="joint_IRC5_to_base" type="fixed">
    <origin rpy="0 0 0" xyz="-0.671632 -0.408099 0.333225"/>
    <parent link="base_link"/>
    <child link="IRC5_1"/>
  </joint>
  <joint name="joint_rear_left_caster_to_base" type="fixed">
    <origin rpy="0 0 0" xyz="-0.583132 -0.362599 0.058225"/>
    <parent link="base_link"/>
    <child link="rear_left_caster_1"/>
  </joint>
  <joint name="joint_rear_right_caster_to_base" type="fixed">
    <origin rpy="0 0 0" xyz="-0.583132 0.366401 0.058225"/>
    <parent link="base_link"/>
    <child link="rear_right_caster_1"/>
  </joint>
  <joint name="joint_front_right_caster_to_base (1)" type="fixed">
    <origin rpy="0 0 0" xyz="0.496877 0.366401 0.058244"/>
    <parent link="base_link"/>
    <child link="front_right_caster_1"/>
  </joint>
  <joint name="joint_front_left_caster_to_base" type="fixed">
    <origin rpy="0 0 0" xyz="0.496877 -0.362599 0.058244"/>
    <parent link="base_link"/>
    <child link="front_left_caster_1"/>
  </joint>
  <joint name="joint_right_drive_wheel_to_base" type="continuous">
    <origin rpy="0 0 0" xyz="0.003368 0.356991 0.108225"/>
    <parent link="base_link"/>
    <child link="right_drive_wheel_1"/>
    <axis xyz="0.0 1.0 0.0"/>
  </joint>
  <joint name="joint_left_drive_wheel_to_base" type="continuous">
    <origin rpy="0 0 0" xyz="0.003368 -0.355189 0.108225"/>
    <parent link="base_link"/>
    <child link="left_drive_wheel_1"/>
    <axis xyz="-0.0 1.0 -0.0"/>
  </joint>
  <joint name="joint_front_lidar_to_base" type="fixed">
    <origin rpy="0 0 0" xyz="-0.586482 -0.368099 0.203225"/>
    <parent link="base_link"/>
    <child link="rear_lidar_1"/>
  </joint>
  <joint name="joint_rear_lidar_to_base" type="fixed">
    <origin rpy="0 0 0" xyz="0.593218 0.371901 0.203225"/>
    <parent link="base_link"/>
    <child link="front_lidar_1"/>
  </joint>
  <joint name="joint_abb_base_0_to_base" type="fixed">
    <origin rpy="0 0 0" xyz="0.45 0.0 0.323225"/>
    <parent link="base_link"/>
    <child link="abb_link_0_1"/>
  </joint>
  <joint name="joint_abb_1_to_abb_0" type="continuous">
    <!-- <joint name="joint_abb_1_to_abb_0" type="fixed"> -->
    <origin rpy="0 0 0" xyz="0.0 0.0 0.139"/>
    <parent link="abb_link_0_1"/>
    <child link="abb_link_1_1"/>
    <axis xyz="-0.0 0.0 1.0"/>
    <limit effort="100" lower="-3.141" upper="3.141" velocity="10"/>
    <!-- <limit effort="0" lower="-3.141" upper="3.141" velocity="3.054"/> -->
  </joint>
  <joint name="joint_abb_2_to_abb_1" type="continuous">
    <!-- <joint name="joint_abb_2_to_abb_1" type="fixed"> -->
    <origin rpy="0 0 0" xyz="0.175 -0.1225 0.3355"/>
    <parent link="abb_link_1_1"/>
    <child link="abb_link_2_1"/>
    <axis xyz="-0.0 -1.0 0.0"/>
    <limit effort="100" lower="-1.570" upper="2.617" velocity="10"/>
    <!-- <limit effort="0" lower="-1.570" upper="2.617" velocity="3.054"/> -->
  </joint>
  <joint name="joint_abb_3_to_abb_2" type="continuous">
    <!-- <joint name="joint_abb_3_to_abb_2" type="fixed"> -->
    <origin rpy="0 0 0" xyz="0.0 -0.0267 1.095"/>
    <parent link="abb_link_2_1"/>
    <child link="abb_link_3_1"/>
    <axis xyz="0.0 1.0 -0.0"/>
    <limit effort="100" lower="-3.141" upper="1.308" velocity="10"/>
    <!-- <limit effort="0" lower="-3.141" upper="1.308" velocity="3.054"/> -->
  </joint>
  <joint name="joint_abb_4_to_abb_3" type="continuous">
    <!-- <joint name="joint_abb_4_to_abb_3" type="fixed"> -->
    <origin rpy="0 0 0" xyz="0.3401 0.1492 0.175"/>
    <parent link="abb_link_3_1"/>
    <child link="abb_link_4_1"/>
    <axis xyz="1.0 0.0 0.0"/>
    <limit effort="100" lower="-6.981" upper="6.981" velocity="10"/>
    <!-- <limit effort="0" lower="-6.981" upper="6.981" velocity="4.363"/> -->
  </joint>
  <joint name="joint_abb_5_to_abb_4" type="continuous">
    <!-- <joint name="joint_abb_5_to_abb_4" type="fixed"> -->
    <origin rpy="0 0 0" xyz="0.8904 -0.0205 0.0"/>
    <parent link="abb_link_4_1"/>
    <child link="abb_link_5_1"/>
    <axis xyz="0.0 1.0 -0.0"/>
    <limit effort="100" lower="-2.181" upper="2.094" velocity="10"/>
    <!-- <limit effort="0" lower="-2.181" upper="2.094" velocity="4.363"/> -->
  </joint>
  <joint name="joint_abb_6_to_abb_5" type="continuous">
    <!-- <joint name="joint_abb_6_to_abb_5" type="fixed"> -->
    <origin rpy="0 0 0" xyz="0.051 0.0205 0.0"/>
    <parent link="abb_link_5_1"/>
    <child link="abb_link_6_1"/>
    <axis xyz="1.0 0.0 0.0"/>
    <limit effort="100" lower="-6.981" upper="6.981" velocity="10"/>
    <!-- <limit effort="0" lower="-6.981" upper="6.981" velocity="6.283"/> -->
  </joint>
  <!-- camera link -->
  <joint name="camera_joint" type="fixed">
    <origin rpy="0 0 0" xyz="1 1 1"/>
    <parent link="base_link"/>
    <child link="camera"/>
  </joint>
</robot>
